<?xml version="1.0"?>
<robot xmlns:xacro="http://www.ros.org/wiki/xacro">
<xacro:include filename="$(find fishbot_description)/urdf/fhishbot/common_inertial.xacro"/>
    <xacro:macro name="wheel_xacro" params="wheel_name xyz">
        <!-- 机器人IMU -->
        <link name="${wheel_name}_link">
            <visual>
                <origin xyz="0.0 0.0 0.0" rpy="1.57079 0.0 0.0"/>
                <geometry>
                    <cylinder radius="0.019" length="0.04"/>
                </geometry>
                <material name="yellow">
                    <color rgba="1.0 1.0 0.0 0.8"/>
                </material>
            </visual>
            <collision>
                <origin xyz="0.0 0.0 0.0" rpy="1.57079 0.0 0.0"/>
                <geometry>
                    <cylinder radius="0.019" length="0.04"/>
                </geometry>
                <material name="yellow">
                    <color rgba="1.0 1.0 0.0 0.8"/>
                </material>
            </collision>
            <xacro:cylinder_inertia m="0.05" r="0.019" h="0.04" />
        </link>

        <!-- 机器人的关节 -->
        <joint name="${wheel_name}_joint" type="continuous">
            <!-- 父子链接将孩子固定到父亲身上 -->
            <parent link="base_link"/>
            <child link="${wheel_name}_link"/>
            <origin xyz="${xyz}" rpy="0.0 0.0 0.0"/>
            <axis xyz="0.0 1.0 0.0"/>
        </joint>
        <gazebo reference="${wheel_name}_link">
            <!-- 切向摩擦系数 -->
            <mu1 value="20.0"/>
            <!-- 法向摩擦系数 -->
            <mu2 value="20.0"/>
            <!-- 刚度系数 -->
            <kp value="1000000000.0"/>
            <!-- 摩擦阻尼 -->
            <kd value="1.0"/>
        </gazebo>
    </xacro:macro>

</robot>